/home/ec2-user/telegram/LAMPA/venv/lib64/python3.6/site-packages/telegram/ext/conversationhandler.py:220: UserWarning: If 'per_message=False', 'CallbackQueryHandler' will not be tracked for every message.
  warnings.warn("If 'per_message=False', 'CallbackQueryHandler' will not be "
2020-05-16 21:53:05,213 - conversation.handlers - INFO - User 220728253: fruit func;
2020-05-16 21:53:09,253 - conversation.handlers - INFO - User 220728253: sound func;
2020-05-16 21:53:11,850 - conversation.handlers - INFO - User 220728253: animal func;
2020-05-16 21:53:13,344 - conversation.handlers - INFO - User 384341805: press /start;
2020-05-16 21:53:13,773 - conversation.handlers - INFO - User 220728253: stickers func;
2020-05-16 21:53:13,892 - conversation.handlers - INFO - User 220728253: consent func;
2020-05-16 21:53:52,907 - conversation.handlers - INFO - User 384341805: press /start;
2020-05-16 23:58:52,146 - telegram.vendor.ptb_urllib3.urllib3.connectionpool - WARNING - Retrying (Retry(total=2, connect=None, read=None, redirect=None)) after connection broken by 'NewConnectionError('<telegram.vendor.ptb_urllib3.urllib3.connection.VerifiedHTTPSConnection object at 0x7ff8967e17f0>: Failed to establish a new connection: [Errno 101] Network is unreachable',)': /bot1200188911:AAGUU56MpLmA-uk-HjjrYX-mCuYAptas004/getUpdates
2020-05-16 23:58:57,153 - telegram.vendor.ptb_urllib3.urllib3.connectionpool - WARNING - Retrying (Retry(total=1, connect=None, read=None, redirect=None)) after connection broken by 'NewConnectionError('<telegram.vendor.ptb_urllib3.urllib3.connection.VerifiedHTTPSConnection object at 0x7ff8967e1be0>: Failed to establish a new connection: [Errno 101] Network is unreachable',)': /bot1200188911:AAGUU56MpLmA-uk-HjjrYX-mCuYAptas004/getUpdates
2020-05-16 23:59:02,160 - telegram.vendor.ptb_urllib3.urllib3.connectionpool - WARNING - Retrying (Retry(total=0, connect=None, read=None, redirect=None)) after connection broken by 'NewConnectionError('<telegram.vendor.ptb_urllib3.urllib3.connection.VerifiedHTTPSConnection object at 0x7ff8967e1780>: Failed to establish a new connection: [Errno 101] Network is unreachable',)': /bot1200188911:AAGUU56MpLmA-uk-HjjrYX-mCuYAptas004/getUpdates
2020-05-16 23:59:07,167 - telegram.ext.updater - ERROR - Error while getting Updates: urllib3 HTTPError HTTPSConnectionPool(host='api.telegram.org', port=443): Max retries exceeded with url: /bot1200188911:AAGUU56MpLmA-uk-HjjrYX-mCuYAptas004/getUpdates (Caused by NewConnectionError('<telegram.vendor.ptb_urllib3.urllib3.connection.VerifiedHTTPSConnection object at 0x7ff8967f7128>: Failed to establish a new connection: [Errno 101] Network is unreachable',))
2020-05-16 23:59:07,167 - telegram.ext.dispatcher - ERROR - No error handlers are registered, logging exception.
Traceback (most recent call last):
  File "/home/ec2-user/telegram/LAMPA/venv/lib64/python3.6/site-packages/telegram/vendor/ptb_urllib3/urllib3/connection.py", line 141, in _new_conn
    (self.host, self.port), self.timeout, **extra_kw)
  File "/home/ec2-user/telegram/LAMPA/venv/lib64/python3.6/site-packages/telegram/vendor/ptb_urllib3/urllib3/util/connection.py", line 83, in create_connection
    raise err
  File "/home/ec2-user/telegram/LAMPA/venv/lib64/python3.6/site-packages/telegram/vendor/ptb_urllib3/urllib3/util/connection.py", line 73, in create_connection
    sock.connect(sa)
OSError: [Errno 101] Network is unreachable

During handling of the above exception, another exception occurred:

Traceback (most recent call last):
  File "/home/ec2-user/telegram/LAMPA/venv/lib64/python3.6/site-packages/telegram/vendor/ptb_urllib3/urllib3/connectionpool.py", line 617, in urlopen
    chunked=chunked)
  File "/home/ec2-user/telegram/LAMPA/venv/lib64/python3.6/site-packages/telegram/vendor/ptb_urllib3/urllib3/connectionpool.py", line 360, in _make_request
    self._validate_conn(conn)
  File "/home/ec2-user/telegram/LAMPA/venv/lib64/python3.6/site-packages/telegram/vendor/ptb_urllib3/urllib3/connectionpool.py", line 857, in _validate_conn
    super(HTTPSConnectionPool, self)._validate_conn(conn)
  File "/home/ec2-user/telegram/LAMPA/venv/lib64/python3.6/site-packages/telegram/vendor/ptb_urllib3/urllib3/connectionpool.py", line 289, in _validate_conn
    conn.connect()
  File "/home/ec2-user/telegram/LAMPA/venv/lib64/python3.6/site-packages/telegram/vendor/ptb_urllib3/urllib3/connection.py", line 284, in connect
    conn = self._new_conn()
  File "/home/ec2-user/telegram/LAMPA/venv/lib64/python3.6/site-packages/telegram/vendor/ptb_urllib3/urllib3/connection.py", line 150, in _new_conn
    self, "Failed to establish a new connection: %s" % e)
telegram.vendor.ptb_urllib3.urllib3.exceptions.NewConnectionError: <telegram.vendor.ptb_urllib3.urllib3.connection.VerifiedHTTPSConnection object at 0x7ff8967f7128>: Failed to establish a new connection: [Errno 101] Network is unreachable

During handling of the above exception, another exception occurred:

Traceback (most recent call last):
  File "/home/ec2-user/telegram/LAMPA/venv/lib64/python3.6/site-packages/telegram/utils/request.py", line 225, in _request_wrapper
    resp = self._con_pool.request(*args, **kwargs)
  File "/home/ec2-user/telegram/LAMPA/venv/lib64/python3.6/site-packages/telegram/vendor/ptb_urllib3/urllib3/request.py", line 70, in request
    **urlopen_kw)
  File "/home/ec2-user/telegram/LAMPA/venv/lib64/python3.6/site-packages/telegram/vendor/ptb_urllib3/urllib3/request.py", line 148, in request_encode_body
    return self.urlopen(method, url, **extra_kw)
  File "/home/ec2-user/telegram/LAMPA/venv/lib64/python3.6/site-packages/telegram/vendor/ptb_urllib3/urllib3/poolmanager.py", line 244, in urlopen
    response = conn.urlopen(method, u.request_uri, **kw)
  File "/home/ec2-user/telegram/LAMPA/venv/lib64/python3.6/site-packages/telegram/vendor/ptb_urllib3/urllib3/connectionpool.py", line 695, in urlopen
    **response_kw)
  File "/home/ec2-user/telegram/LAMPA/venv/lib64/python3.6/site-packages/telegram/vendor/ptb_urllib3/urllib3/connectionpool.py", line 695, in urlopen
    **response_kw)
  File "/home/ec2-user/telegram/LAMPA/venv/lib64/python3.6/site-packages/telegram/vendor/ptb_urllib3/urllib3/connectionpool.py", line 695, in urlopen
    **response_kw)
  File "/home/ec2-user/telegram/LAMPA/venv/lib64/python3.6/site-packages/telegram/vendor/ptb_urllib3/urllib3/connectionpool.py", line 666, in urlopen
    _stacktrace=sys.exc_info()[2])
  File "/home/ec2-user/telegram/LAMPA/venv/lib64/python3.6/site-packages/telegram/vendor/ptb_urllib3/urllib3/util/retry.py", line 376, in increment
    raise MaxRetryError(_pool, url, error or ResponseError(cause))
telegram.vendor.ptb_urllib3.urllib3.exceptions.MaxRetryError: HTTPSConnectionPool(host='api.telegram.org', port=443): Max retries exceeded with url: /bot1200188911:AAGUU56MpLmA-uk-HjjrYX-mCuYAptas004/getUpdates (Caused by NewConnectionError('<telegram.vendor.ptb_urllib3.urllib3.connection.VerifiedHTTPSConnection object at 0x7ff8967f7128>: Failed to establish a new connection: [Errno 101] Network is unreachable',))

During handling of the above exception, another exception occurred:

Traceback (most recent call last):
  File "/home/ec2-user/telegram/LAMPA/venv/lib64/python3.6/site-packages/telegram/ext/updater.py", line 380, in _network_loop_retry
    if not action_cb():
  File "/home/ec2-user/telegram/LAMPA/venv/lib64/python3.6/site-packages/telegram/ext/updater.py", line 341, in polling_action_cb
    allowed_updates=allowed_updates)
  File "<decorator-gen-31>", line 2, in get_updates
  File "/home/ec2-user/telegram/LAMPA/venv/lib64/python3.6/site-packages/telegram/bot.py", line 70, in decorator
    result = func(*args, **kwargs)
  File "/home/ec2-user/telegram/LAMPA/venv/lib64/python3.6/site-packages/telegram/bot.py", line 2136, in get_updates
    result = self._request.post(url, data, timeout=float(read_latency) + float(timeout))
  File "/home/ec2-user/telegram/LAMPA/venv/lib64/python3.6/site-packages/telegram/utils/request.py", line 334, in post
    **urlopen_kwargs)
  File "/home/ec2-user/telegram/LAMPA/venv/lib64/python3.6/site-packages/telegram/utils/request.py", line 231, in _request_wrapper
    raise NetworkError('urllib3 HTTPError {0}'.format(error))
telegram.error.NetworkError: urllib3 HTTPError HTTPSConnectionPool(host='api.telegram.org', port=443): Max retries exceeded with url: /bot1200188911:AAGUU56MpLmA-uk-HjjrYX-mCuYAptas004/getUpdates (Caused by NewConnectionError('<telegram.vendor.ptb_urllib3.urllib3.connection.VerifiedHTTPSConnection object at 0x7ff8967f7128>: Failed to establish a new connection: [Errno 101] Network is unreachable',))
2020-05-16 23:59:13,172 - telegram.vendor.ptb_urllib3.urllib3.connectionpool - WARNING - Retrying (Retry(total=2, connect=None, read=None, redirect=None)) after connection broken by 'NewConnectionError('<telegram.vendor.ptb_urllib3.urllib3.connection.VerifiedHTTPSConnection object at 0x7ff8967e1b38>: Failed to establish a new connection: [Errno 101] Network is unreachable',)': /bot1200188911:AAGUU56MpLmA-uk-HjjrYX-mCuYAptas004/getUpdates
2020-05-16 23:59:18,177 - telegram.vendor.ptb_urllib3.urllib3.connectionpool - WARNING - Retrying (Retry(total=1, connect=None, read=None, redirect=None)) after connection broken by 'NewConnectionError('<telegram.vendor.ptb_urllib3.urllib3.connection.VerifiedHTTPSConnection object at 0x7ff8967f7470>: Failed to establish a new connection: [Errno 101] Network is unreachable',)': /bot1200188911:AAGUU56MpLmA-uk-HjjrYX-mCuYAptas004/getUpdates
2020-05-16 23:59:23,180 - telegram.vendor.ptb_urllib3.urllib3.connectionpool - WARNING - Retrying (Retry(total=0, connect=None, read=None, redirect=None)) after connection broken by 'NewConnectionError('<telegram.vendor.ptb_urllib3.urllib3.connection.VerifiedHTTPSConnection object at 0x7ff89f3a8240>: Failed to establish a new connection: [Errno 101] Network is unreachable',)': /bot1200188911:AAGUU56MpLmA-uk-HjjrYX-mCuYAptas004/getUpdates
2020-05-16 23:59:28,186 - telegram.ext.updater - ERROR - Error while getting Updates: urllib3 HTTPError HTTPSConnectionPool(host='api.telegram.org', port=443): Max retries exceeded with url: /bot1200188911:AAGUU56MpLmA-uk-HjjrYX-mCuYAptas004/getUpdates (Caused by NewConnectionError('<telegram.vendor.ptb_urllib3.urllib3.connection.VerifiedHTTPSConnection object at 0x7ff89f3a83c8>: Failed to establish a new connection: [Errno 101] Network is unreachable',))
2020-05-16 23:59:28,187 - telegram.ext.dispatcher - ERROR - No error handlers are registered, logging exception.
Traceback (most recent call last):
  File "/home/ec2-user/telegram/LAMPA/venv/lib64/python3.6/site-packages/telegram/vendor/ptb_urllib3/urllib3/connection.py", line 141, in _new_conn
    (self.host, self.port), self.timeout, **extra_kw)
  File "/home/ec2-user/telegram/LAMPA/venv/lib64/python3.6/site-packages/telegram/vendor/ptb_urllib3/urllib3/util/connection.py", line 83, in create_connection
    raise err
  File "/home/ec2-user/telegram/LAMPA/venv/lib64/python3.6/site-packages/telegram/vendor/ptb_urllib3/urllib3/util/connection.py", line 73, in create_connection
    sock.connect(sa)
OSError: [Errno 101] Network is unreachable

During handling of the above exception, another exception occurred:

Traceback (most recent call last):
  File "/home/ec2-user/telegram/LAMPA/venv/lib64/python3.6/site-packages/telegram/vendor/ptb_urllib3/urllib3/connectionpool.py", line 617, in urlopen
    chunked=chunked)
  File "/home/ec2-user/telegram/LAMPA/venv/lib64/python3.6/site-packages/telegram/vendor/ptb_urllib3/urllib3/connectionpool.py", line 360, in _make_request
    self._validate_conn(conn)
  File "/home/ec2-user/telegram/LAMPA/venv/lib64/python3.6/site-packages/telegram/vendor/ptb_urllib3/urllib3/connectionpool.py", line 857, in _validate_conn
    super(HTTPSConnectionPool, self)._validate_conn(conn)
  File "/home/ec2-user/telegram/LAMPA/venv/lib64/python3.6/site-packages/telegram/vendor/ptb_urllib3/urllib3/connectionpool.py", line 289, in _validate_conn
    conn.connect()
  File "/home/ec2-user/telegram/LAMPA/venv/lib64/python3.6/site-packages/telegram/vendor/ptb_urllib3/urllib3/connection.py", line 284, in connect
    conn = self._new_conn()
  File "/home/ec2-user/telegram/LAMPA/venv/lib64/python3.6/site-packages/telegram/vendor/ptb_urllib3/urllib3/connection.py", line 150, in _new_conn
    self, "Failed to establish a new connection: %s" % e)
telegram.vendor.ptb_urllib3.urllib3.exceptions.NewConnectionError: <telegram.vendor.ptb_urllib3.urllib3.connection.VerifiedHTTPSConnection object at 0x7ff89f3a83c8>: Failed to establish a new connection: [Errno 101] Network is unreachable

During handling of the above exception, another exception occurred:

Traceback (most recent call last):
  File "/home/ec2-user/telegram/LAMPA/venv/lib64/python3.6/site-packages/telegram/utils/request.py", line 225, in _request_wrapper
    resp = self._con_pool.request(*args, **kwargs)
  File "/home/ec2-user/telegram/LAMPA/venv/lib64/python3.6/site-packages/telegram/vendor/ptb_urllib3/urllib3/request.py", line 70, in request
    **urlopen_kw)
  File "/home/ec2-user/telegram/LAMPA/venv/lib64/python3.6/site-packages/telegram/vendor/ptb_urllib3/urllib3/request.py", line 148, in request_encode_body
    return self.urlopen(method, url, **extra_kw)
  File "/home/ec2-user/telegram/LAMPA/venv/lib64/python3.6/site-packages/telegram/vendor/ptb_urllib3/urllib3/poolmanager.py", line 244, in urlopen
    response = conn.urlopen(method, u.request_uri, **kw)
  File "/home/ec2-user/telegram/LAMPA/venv/lib64/python3.6/site-packages/telegram/vendor/ptb_urllib3/urllib3/connectionpool.py", line 695, in urlopen
    **response_kw)
  File "/home/ec2-user/telegram/LAMPA/venv/lib64/python3.6/site-packages/telegram/vendor/ptb_urllib3/urllib3/connectionpool.py", line 695, in urlopen
    **response_kw)
  File "/home/ec2-user/telegram/LAMPA/venv/lib64/python3.6/site-packages/telegram/vendor/ptb_urllib3/urllib3/connectionpool.py", line 695, in urlopen
    **response_kw)
  File "/home/ec2-user/telegram/LAMPA/venv/lib64/python3.6/site-packages/telegram/vendor/ptb_urllib3/urllib3/connectionpool.py", line 666, in urlopen
    _stacktrace=sys.exc_info()[2])
  File "/home/ec2-user/telegram/LAMPA/venv/lib64/python3.6/site-packages/telegram/vendor/ptb_urllib3/urllib3/util/retry.py", line 376, in increment
    raise MaxRetryError(_pool, url, error or ResponseError(cause))
telegram.vendor.ptb_urllib3.urllib3.exceptions.MaxRetryError: HTTPSConnectionPool(host='api.telegram.org', port=443): Max retries exceeded with url: /bot1200188911:AAGUU56MpLmA-uk-HjjrYX-mCuYAptas004/getUpdates (Caused by NewConnectionError('<telegram.vendor.ptb_urllib3.urllib3.connection.VerifiedHTTPSConnection object at 0x7ff89f3a83c8>: Failed to establish a new connection: [Errno 101] Network is unreachable',))

During handling of the above exception, another exception occurred:

Traceback (most recent call last):
  File "/home/ec2-user/telegram/LAMPA/venv/lib64/python3.6/site-packages/telegram/ext/updater.py", line 380, in _network_loop_retry
    if not action_cb():
  File "/home/ec2-user/telegram/LAMPA/venv/lib64/python3.6/site-packages/telegram/ext/updater.py", line 341, in polling_action_cb
    allowed_updates=allowed_updates)
  File "<decorator-gen-31>", line 2, in get_updates
  File "/home/ec2-user/telegram/LAMPA/venv/lib64/python3.6/site-packages/telegram/bot.py", line 70, in decorator
    result = func(*args, **kwargs)
  File "/home/ec2-user/telegram/LAMPA/venv/lib64/python3.6/site-packages/telegram/bot.py", line 2136, in get_updates
    result = self._request.post(url, data, timeout=float(read_latency) + float(timeout))
  File "/home/ec2-user/telegram/LAMPA/venv/lib64/python3.6/site-packages/telegram/utils/request.py", line 334, in post
    **urlopen_kwargs)
  File "/home/ec2-user/telegram/LAMPA/venv/lib64/python3.6/site-packages/telegram/utils/request.py", line 231, in _request_wrapper
    raise NetworkError('urllib3 HTTPError {0}'.format(error))
telegram.error.NetworkError: urllib3 HTTPError HTTPSConnectionPool(host='api.telegram.org', port=443): Max retries exceeded with url: /bot1200188911:AAGUU56MpLmA-uk-HjjrYX-mCuYAptas004/getUpdates (Caused by NewConnectionError('<telegram.vendor.ptb_urllib3.urllib3.connection.VerifiedHTTPSConnection object at 0x7ff89f3a83c8>: Failed to establish a new connection: [Errno 101] Network is unreachable',))
2020-05-16 23:59:34,696 - telegram.vendor.ptb_urllib3.urllib3.connectionpool - WARNING - Retrying (Retry(total=2, connect=None, read=None, redirect=None)) after connection broken by 'NewConnectionError('<telegram.vendor.ptb_urllib3.urllib3.connection.VerifiedHTTPSConnection object at 0x7ff8967f7358>: Failed to establish a new connection: [Errno 101] Network is unreachable',)': /bot1200188911:AAGUU56MpLmA-uk-HjjrYX-mCuYAptas004/getUpdates
2020-05-16 23:59:39,702 - telegram.vendor.ptb_urllib3.urllib3.connectionpool - WARNING - Retrying (Retry(total=1, connect=None, read=None, redirect=None)) after connection broken by 'NewConnectionError('<telegram.vendor.ptb_urllib3.urllib3.connection.VerifiedHTTPSConnection object at 0x7ff8967f7c50>: Failed to establish a new connection: [Errno 101] Network is unreachable',)': /bot1200188911:AAGUU56MpLmA-uk-HjjrYX-mCuYAptas004/getUpdates
2020-05-16 23:59:44,709 - telegram.vendor.ptb_urllib3.urllib3.connectionpool - WARNING - Retrying (Retry(total=0, connect=None, read=None, redirect=None)) after connection broken by 'NewConnectionError('<telegram.vendor.ptb_urllib3.urllib3.connection.VerifiedHTTPSConnection object at 0x7ff8967f7cf8>: Failed to establish a new connection: [Errno 101] Network is unreachable',)': /bot1200188911:AAGUU56MpLmA-uk-HjjrYX-mCuYAptas004/getUpdates
2020-05-16 23:59:49,716 - telegram.ext.updater - ERROR - Error while getting Updates: urllib3 HTTPError HTTPSConnectionPool(host='api.telegram.org', port=443): Max retries exceeded with url: /bot1200188911:AAGUU56MpLmA-uk-HjjrYX-mCuYAptas004/getUpdates (Caused by NewConnectionError('<telegram.vendor.ptb_urllib3.urllib3.connection.VerifiedHTTPSConnection object at 0x7ff8967f7dd8>: Failed to establish a new connection: [Errno 101] Network is unreachable',))
2020-05-16 23:59:49,716 - telegram.ext.dispatcher - ERROR - No error handlers are registered, logging exception.
Traceback (most recent call last):
  File "/home/ec2-user/telegram/LAMPA/venv/lib64/python3.6/site-packages/telegram/vendor/ptb_urllib3/urllib3/connection.py", line 141, in _new_conn
    (self.host, self.port), self.timeout, **extra_kw)
  File "/home/ec2-user/telegram/LAMPA/venv/lib64/python3.6/site-packages/telegram/vendor/ptb_urllib3/urllib3/util/connection.py", line 83, in create_connection
    raise err
  File "/home/ec2-user/telegram/LAMPA/venv/lib64/python3.6/site-packages/telegram/vendor/ptb_urllib3/urllib3/util/connection.py", line 73, in create_connection
    sock.connect(sa)
OSError: [Errno 101] Network is unreachable

During handling of the above exception, another exception occurred:

Traceback (most recent call last):
  File "/home/ec2-user/telegram/LAMPA/venv/lib64/python3.6/site-packages/telegram/vendor/ptb_urllib3/urllib3/connectionpool.py", line 617, in urlopen
    chunked=chunked)
  File "/home/ec2-user/telegram/LAMPA/venv/lib64/python3.6/site-packages/telegram/vendor/ptb_urllib3/urllib3/connectionpool.py", line 360, in _make_request
    self._validate_conn(conn)
  File "/home/ec2-user/telegram/LAMPA/venv/lib64/python3.6/site-packages/telegram/vendor/ptb_urllib3/urllib3/connectionpool.py", line 857, in _validate_conn
    super(HTTPSConnectionPool, self)._validate_conn(conn)
  File "/home/ec2-user/telegram/LAMPA/venv/lib64/python3.6/site-packages/telegram/vendor/ptb_urllib3/urllib3/connectionpool.py", line 289, in _validate_conn
    conn.connect()
  File "/home/ec2-user/telegram/LAMPA/venv/lib64/python3.6/site-packages/telegram/vendor/ptb_urllib3/urllib3/connection.py", line 284, in connect
    conn = self._new_conn()
  File "/home/ec2-user/telegram/LAMPA/venv/lib64/python3.6/site-packages/telegram/vendor/ptb_urllib3/urllib3/connection.py", line 150, in _new_conn
    self, "Failed to establish a new connection: %s" % e)
telegram.vendor.ptb_urllib3.urllib3.exceptions.NewConnectionError: <telegram.vendor.ptb_urllib3.urllib3.connection.VerifiedHTTPSConnection object at 0x7ff8967f7dd8>: Failed to establish a new connection: [Errno 101] Network is unreachable

During handling of the above exception, another exception occurred:

Traceback (most recent call last):
  File "/home/ec2-user/telegram/LAMPA/venv/lib64/python3.6/site-packages/telegram/utils/request.py", line 225, in _request_wrapper
    resp = self._con_pool.request(*args, **kwargs)
  File "/home/ec2-user/telegram/LAMPA/venv/lib64/python3.6/site-packages/telegram/vendor/ptb_urllib3/urllib3/request.py", line 70, in request
    **urlopen_kw)
  File "/home/ec2-user/telegram/LAMPA/venv/lib64/python3.6/site-packages/telegram/vendor/ptb_urllib3/urllib3/request.py", line 148, in request_encode_body
    return self.urlopen(method, url, **extra_kw)
  File "/home/ec2-user/telegram/LAMPA/venv/lib64/python3.6/site-packages/telegram/vendor/ptb_urllib3/urllib3/poolmanager.py", line 244, in urlopen
    response = conn.urlopen(method, u.request_uri, **kw)
  File "/home/ec2-user/telegram/LAMPA/venv/lib64/python3.6/site-packages/telegram/vendor/ptb_urllib3/urllib3/connectionpool.py", line 695, in urlopen
    **response_kw)
  File "/home/ec2-user/telegram/LAMPA/venv/lib64/python3.6/site-packages/telegram/vendor/ptb_urllib3/urllib3/connectionpool.py", line 695, in urlopen
    **response_kw)
  File "/home/ec2-user/telegram/LAMPA/venv/lib64/python3.6/site-packages/telegram/vendor/ptb_urllib3/urllib3/connectionpool.py", line 695, in urlopen
    **response_kw)
  File "/home/ec2-user/telegram/LAMPA/venv/lib64/python3.6/site-packages/telegram/vendor/ptb_urllib3/urllib3/connectionpool.py", line 666, in urlopen
    _stacktrace=sys.exc_info()[2])
  File "/home/ec2-user/telegram/LAMPA/venv/lib64/python3.6/site-packages/telegram/vendor/ptb_urllib3/urllib3/util/retry.py", line 376, in increment
    raise MaxRetryError(_pool, url, error or ResponseError(cause))
telegram.vendor.ptb_urllib3.urllib3.exceptions.MaxRetryError: HTTPSConnectionPool(host='api.telegram.org', port=443): Max retries exceeded with url: /bot1200188911:AAGUU56MpLmA-uk-HjjrYX-mCuYAptas004/getUpdates (Caused by NewConnectionError('<telegram.vendor.ptb_urllib3.urllib3.connection.VerifiedHTTPSConnection object at 0x7ff8967f7dd8>: Failed to establish a new connection: [Errno 101] Network is unreachable',))

During handling of the above exception, another exception occurred:

Traceback (most recent call last):
  File "/home/ec2-user/telegram/LAMPA/venv/lib64/python3.6/site-packages/telegram/ext/updater.py", line 380, in _network_loop_retry
    if not action_cb():
  File "/home/ec2-user/telegram/LAMPA/venv/lib64/python3.6/site-packages/telegram/ext/updater.py", line 341, in polling_action_cb
    allowed_updates=allowed_updates)
  File "<decorator-gen-31>", line 2, in get_updates
  File "/home/ec2-user/telegram/LAMPA/venv/lib64/python3.6/site-packages/telegram/bot.py", line 70, in decorator
    result = func(*args, **kwargs)
  File "/home/ec2-user/telegram/LAMPA/venv/lib64/python3.6/site-packages/telegram/bot.py", line 2136, in get_updates
    result = self._request.post(url, data, timeout=float(read_latency) + float(timeout))
  File "/home/ec2-user/telegram/LAMPA/venv/lib64/python3.6/site-packages/telegram/utils/request.py", line 334, in post
    **urlopen_kwargs)
  File "/home/ec2-user/telegram/LAMPA/venv/lib64/python3.6/site-packages/telegram/utils/request.py", line 231, in _request_wrapper
    raise NetworkError('urllib3 HTTPError {0}'.format(error))
telegram.error.NetworkError: urllib3 HTTPError HTTPSConnectionPool(host='api.telegram.org', port=443): Max retries exceeded with url: /bot1200188911:AAGUU56MpLmA-uk-HjjrYX-mCuYAptas004/getUpdates (Caused by NewConnectionError('<telegram.vendor.ptb_urllib3.urllib3.connection.VerifiedHTTPSConnection object at 0x7ff8967f7dd8>: Failed to establish a new connection: [Errno 101] Network is unreachable',))
2020-05-16 23:59:56,977 - telegram.vendor.ptb_urllib3.urllib3.connectionpool - WARNING - Retrying (Retry(total=2, connect=None, read=None, redirect=None)) after connection broken by 'NewConnectionError('<telegram.vendor.ptb_urllib3.urllib3.connection.VerifiedHTTPSConnection object at 0x7ff8967f71d0>: Failed to establish a new connection: [Errno 101] Network is unreachable',)': /bot1200188911:AAGUU56MpLmA-uk-HjjrYX-mCuYAptas004/getUpdates
2020-05-17 00:00:01,984 - telegram.vendor.ptb_urllib3.urllib3.connectionpool - WARNING - Retrying (Retry(total=1, connect=None, read=None, redirect=None)) after connection broken by 'NewConnectionError('<telegram.vendor.ptb_urllib3.urllib3.connection.VerifiedHTTPSConnection object at 0x7ff8947200f0>: Failed to establish a new connection: [Errno 101] Network is unreachable',)': /bot1200188911:AAGUU56MpLmA-uk-HjjrYX-mCuYAptas004/getUpdates
2020-05-17 00:00:06,986 - telegram.vendor.ptb_urllib3.urllib3.connectionpool - WARNING - Retrying (Retry(total=0, connect=None, read=None, redirect=None)) after connection broken by 'NewConnectionError('<telegram.vendor.ptb_urllib3.urllib3.connection.VerifiedHTTPSConnection object at 0x7ff894720198>: Failed to establish a new connection: [Errno 101] Network is unreachable',)': /bot1200188911:AAGUU56MpLmA-uk-HjjrYX-mCuYAptas004/getUpdates
2020-05-17 00:00:11,994 - telegram.ext.updater - ERROR - Error while getting Updates: urllib3 HTTPError HTTPSConnectionPool(host='api.telegram.org', port=443): Max retries exceeded with url: /bot1200188911:AAGUU56MpLmA-uk-HjjrYX-mCuYAptas004/getUpdates (Caused by NewConnectionError('<telegram.vendor.ptb_urllib3.urllib3.connection.VerifiedHTTPSConnection object at 0x7ff894720278>: Failed to establish a new connection: [Errno 101] Network is unreachable',))
2020-05-17 00:00:11,994 - telegram.ext.dispatcher - ERROR - No error handlers are registered, logging exception.
Traceback (most recent call last):
  File "/home/ec2-user/telegram/LAMPA/venv/lib64/python3.6/site-packages/telegram/vendor/ptb_urllib3/urllib3/connection.py", line 141, in _new_conn
    (self.host, self.port), self.timeout, **extra_kw)
  File "/home/ec2-user/telegram/LAMPA/venv/lib64/python3.6/site-packages/telegram/vendor/ptb_urllib3/urllib3/util/connection.py", line 83, in create_connection
    raise err
  File "/home/ec2-user/telegram/LAMPA/venv/lib64/python3.6/site-packages/telegram/vendor/ptb_urllib3/urllib3/util/connection.py", line 73, in create_connection
    sock.connect(sa)
OSError: [Errno 101] Network is unreachable

During handling of the above exception, another exception occurred:

Traceback (most recent call last):
  File "/home/ec2-user/telegram/LAMPA/venv/lib64/python3.6/site-packages/telegram/vendor/ptb_urllib3/urllib3/connectionpool.py", line 617, in urlopen
    chunked=chunked)
  File "/home/ec2-user/telegram/LAMPA/venv/lib64/python3.6/site-packages/telegram/vendor/ptb_urllib3/urllib3/connectionpool.py", line 360, in _make_request
    self._validate_conn(conn)
  File "/home/ec2-user/telegram/LAMPA/venv/lib64/python3.6/site-packages/telegram/vendor/ptb_urllib3/urllib3/connectionpool.py", line 857, in _validate_conn
    super(HTTPSConnectionPool, self)._validate_conn(conn)
  File "/home/ec2-user/telegram/LAMPA/venv/lib64/python3.6/site-packages/telegram/vendor/ptb_urllib3/urllib3/connectionpool.py", line 289, in _validate_conn
    conn.connect()
  File "/home/ec2-user/telegram/LAMPA/venv/lib64/python3.6/site-packages/telegram/vendor/ptb_urllib3/urllib3/connection.py", line 284, in connect
    conn = self._new_conn()
  File "/home/ec2-user/telegram/LAMPA/venv/lib64/python3.6/site-packages/telegram/vendor/ptb_urllib3/urllib3/connection.py", line 150, in _new_conn
    self, "Failed to establish a new connection: %s" % e)
telegram.vendor.ptb_urllib3.urllib3.exceptions.NewConnectionError: <telegram.vendor.ptb_urllib3.urllib3.connection.VerifiedHTTPSConnection object at 0x7ff894720278>: Failed to establish a new connection: [Errno 101] Network is unreachable

During handling of the above exception, another exception occurred:

Traceback (most recent call last):
  File "/home/ec2-user/telegram/LAMPA/venv/lib64/python3.6/site-packages/telegram/utils/request.py", line 225, in _request_wrapper
    resp = self._con_pool.request(*args, **kwargs)
  File "/home/ec2-user/telegram/LAMPA/venv/lib64/python3.6/site-packages/telegram/vendor/ptb_urllib3/urllib3/request.py", line 70, in request
    **urlopen_kw)
  File "/home/ec2-user/telegram/LAMPA/venv/lib64/python3.6/site-packages/telegram/vendor/ptb_urllib3/urllib3/request.py", line 148, in request_encode_body
    return self.urlopen(method, url, **extra_kw)
  File "/home/ec2-user/telegram/LAMPA/venv/lib64/python3.6/site-packages/telegram/vendor/ptb_urllib3/urllib3/poolmanager.py", line 244, in urlopen
    response = conn.urlopen(method, u.request_uri, **kw)
  File "/home/ec2-user/telegram/LAMPA/venv/lib64/python3.6/site-packages/telegram/vendor/ptb_urllib3/urllib3/connectionpool.py", line 695, in urlopen
    **response_kw)
  File "/home/ec2-user/telegram/LAMPA/venv/lib64/python3.6/site-packages/telegram/vendor/ptb_urllib3/urllib3/connectionpool.py", line 695, in urlopen
    **response_kw)
  File "/home/ec2-user/telegram/LAMPA/venv/lib64/python3.6/site-packages/telegram/vendor/ptb_urllib3/urllib3/connectionpool.py", line 695, in urlopen
    **response_kw)
  File "/home/ec2-user/telegram/LAMPA/venv/lib64/python3.6/site-packages/telegram/vendor/ptb_urllib3/urllib3/connectionpool.py", line 666, in urlopen
    _stacktrace=sys.exc_info()[2])
  File "/home/ec2-user/telegram/LAMPA/venv/lib64/python3.6/site-packages/telegram/vendor/ptb_urllib3/urllib3/util/retry.py", line 376, in increment
    raise MaxRetryError(_pool, url, error or ResponseError(cause))
telegram.vendor.ptb_urllib3.urllib3.exceptions.MaxRetryError: HTTPSConnectionPool(host='api.telegram.org', port=443): Max retries exceeded with url: /bot1200188911:AAGUU56MpLmA-uk-HjjrYX-mCuYAptas004/getUpdates (Caused by NewConnectionError('<telegram.vendor.ptb_urllib3.urllib3.connection.VerifiedHTTPSConnection object at 0x7ff894720278>: Failed to establish a new connection: [Errno 101] Network is unreachable',))

During handling of the above exception, another exception occurred:

Traceback (most recent call last):
  File "/home/ec2-user/telegram/LAMPA/venv/lib64/python3.6/site-packages/telegram/ext/updater.py", line 380, in _network_loop_retry
    if not action_cb():
  File "/home/ec2-user/telegram/LAMPA/venv/lib64/python3.6/site-packages/telegram/ext/updater.py", line 341, in polling_action_cb
    allowed_updates=allowed_updates)
  File "<decorator-gen-31>", line 2, in get_updates
  File "/home/ec2-user/telegram/LAMPA/venv/lib64/python3.6/site-packages/telegram/bot.py", line 70, in decorator
    result = func(*args, **kwargs)
  File "/home/ec2-user/telegram/LAMPA/venv/lib64/python3.6/site-packages/telegram/bot.py", line 2136, in get_updates
    result = self._request.post(url, data, timeout=float(read_latency) + float(timeout))
  File "/home/ec2-user/telegram/LAMPA/venv/lib64/python3.6/site-packages/telegram/utils/request.py", line 334, in post
    **urlopen_kwargs)
  File "/home/ec2-user/telegram/LAMPA/venv/lib64/python3.6/site-packages/telegram/utils/request.py", line 231, in _request_wrapper
    raise NetworkError('urllib3 HTTPError {0}'.format(error))
telegram.error.NetworkError: urllib3 HTTPError HTTPSConnectionPool(host='api.telegram.org', port=443): Max retries exceeded with url: /bot1200188911:AAGUU56MpLmA-uk-HjjrYX-mCuYAptas004/getUpdates (Caused by NewConnectionError('<telegram.vendor.ptb_urllib3.urllib3.connection.VerifiedHTTPSConnection object at 0x7ff894720278>: Failed to establish a new connection: [Errno 101] Network is unreachable',))
2020-05-17 00:00:20,375 - telegram.vendor.ptb_urllib3.urllib3.connectionpool - WARNING - Retrying (Retry(total=2, connect=None, read=None, redirect=None)) after connection broken by 'NewConnectionError('<telegram.vendor.ptb_urllib3.urllib3.connection.VerifiedHTTPSConnection object at 0x7ff894720048>: Failed to establish a new connection: [Errno 101] Network is unreachable',)': /bot1200188911:AAGUU56MpLmA-uk-HjjrYX-mCuYAptas004/getUpdates
2020-05-17 00:00:25,379 - telegram.vendor.ptb_urllib3.urllib3.connectionpool - WARNING - Retrying (Retry(total=1, connect=None, read=None, redirect=None)) after connection broken by 'NewConnectionError('<telegram.vendor.ptb_urllib3.urllib3.connection.VerifiedHTTPSConnection object at 0x7ff894720550>: Failed to establish a new connection: [Errno 101] Network is unreachable',)': /bot1200188911:AAGUU56MpLmA-uk-HjjrYX-mCuYAptas004/getUpdates
2020-05-17 00:00:30,385 - telegram.vendor.ptb_urllib3.urllib3.connectionpool - WARNING - Retrying (Retry(total=0, connect=None, read=None, redirect=None)) after connection broken by 'NewConnectionError('<telegram.vendor.ptb_urllib3.urllib3.connection.VerifiedHTTPSConnection object at 0x7ff8947205f8>: Failed to establish a new connection: [Errno 101] Network is unreachable',)': /bot1200188911:AAGUU56MpLmA-uk-HjjrYX-mCuYAptas004/getUpdates
2020-05-17 00:00:35,391 - telegram.ext.updater - ERROR - Error while getting Updates: urllib3 HTTPError HTTPSConnectionPool(host='api.telegram.org', port=443): Max retries exceeded with url: /bot1200188911:AAGUU56MpLmA-uk-HjjrYX-mCuYAptas004/getUpdates (Caused by NewConnectionError('<telegram.vendor.ptb_urllib3.urllib3.connection.VerifiedHTTPSConnection object at 0x7ff8947206d8>: Failed to establish a new connection: [Errno 101] Network is unreachable',))
2020-05-17 00:00:35,391 - telegram.ext.dispatcher - ERROR - No error handlers are registered, logging exception.
Traceback (most recent call last):
  File "/home/ec2-user/telegram/LAMPA/venv/lib64/python3.6/site-packages/telegram/vendor/ptb_urllib3/urllib3/connection.py", line 141, in _new_conn
    (self.host, self.port), self.timeout, **extra_kw)
  File "/home/ec2-user/telegram/LAMPA/venv/lib64/python3.6/site-packages/telegram/vendor/ptb_urllib3/urllib3/util/connection.py", line 83, in create_connection
    raise err
  File "/home/ec2-user/telegram/LAMPA/venv/lib64/python3.6/site-packages/telegram/vendor/ptb_urllib3/urllib3/util/connection.py", line 73, in create_connection
    sock.connect(sa)
OSError: [Errno 101] Network is unreachable

During handling of the above exception, another exception occurred:

Traceback (most recent call last):
  File "/home/ec2-user/telegram/LAMPA/venv/lib64/python3.6/site-packages/telegram/vendor/ptb_urllib3/urllib3/connectionpool.py", line 617, in urlopen
    chunked=chunked)
  File "/home/ec2-user/telegram/LAMPA/venv/lib64/python3.6/site-packages/telegram/vendor/ptb_urllib3/urllib3/connectionpool.py", line 360, in _make_request
    self._validate_conn(conn)
  File "/home/ec2-user/telegram/LAMPA/venv/lib64/python3.6/site-packages/telegram/vendor/ptb_urllib3/urllib3/connectionpool.py", line 857, in _validate_conn
    super(HTTPSConnectionPool, self)._validate_conn(conn)
  File "/home/ec2-user/telegram/LAMPA/venv/lib64/python3.6/site-packages/telegram/vendor/ptb_urllib3/urllib3/connectionpool.py", line 289, in _validate_conn
    conn.connect()
  File "/home/ec2-user/telegram/LAMPA/venv/lib64/python3.6/site-packages/telegram/vendor/ptb_urllib3/urllib3/connection.py", line 284, in connect
    conn = self._new_conn()
  File "/home/ec2-user/telegram/LAMPA/venv/lib64/python3.6/site-packages/telegram/vendor/ptb_urllib3/urllib3/connection.py", line 150, in _new_conn
    self, "Failed to establish a new connection: %s" % e)
telegram.vendor.ptb_urllib3.urllib3.exceptions.NewConnectionError: <telegram.vendor.ptb_urllib3.urllib3.connection.VerifiedHTTPSConnection object at 0x7ff8947206d8>: Failed to establish a new connection: [Errno 101] Network is unreachable

During handling of the above exception, another exception occurred:

Traceback (most recent call last):
  File "/home/ec2-user/telegram/LAMPA/venv/lib64/python3.6/site-packages/telegram/utils/request.py", line 225, in _request_wrapper
    resp = self._con_pool.request(*args, **kwargs)
  File "/home/ec2-user/telegram/LAMPA/venv/lib64/python3.6/site-packages/telegram/vendor/ptb_urllib3/urllib3/request.py", line 70, in request
    **urlopen_kw)
  File "/home/ec2-user/telegram/LAMPA/venv/lib64/python3.6/site-packages/telegram/vendor/ptb_urllib3/urllib3/request.py", line 148, in request_encode_body
    return self.urlopen(method, url, **extra_kw)
  File "/home/ec2-user/telegram/LAMPA/venv/lib64/python3.6/site-packages/telegram/vendor/ptb_urllib3/urllib3/poolmanager.py", line 244, in urlopen
    response = conn.urlopen(method, u.request_uri, **kw)
  File "/home/ec2-user/telegram/LAMPA/venv/lib64/python3.6/site-packages/telegram/vendor/ptb_urllib3/urllib3/connectionpool.py", line 695, in urlopen
    **response_kw)
  File "/home/ec2-user/telegram/LAMPA/venv/lib64/python3.6/site-packages/telegram/vendor/ptb_urllib3/urllib3/connectionpool.py", line 695, in urlopen
    **response_kw)
  File "/home/ec2-user/telegram/LAMPA/venv/lib64/python3.6/site-packages/telegram/vendor/ptb_urllib3/urllib3/connectionpool.py", line 695, in urlopen
    **response_kw)
  File "/home/ec2-user/telegram/LAMPA/venv/lib64/python3.6/site-packages/telegram/vendor/ptb_urllib3/urllib3/connectionpool.py", line 666, in urlopen
    _stacktrace=sys.exc_info()[2])
  File "/home/ec2-user/telegram/LAMPA/venv/lib64/python3.6/site-packages/telegram/vendor/ptb_urllib3/urllib3/util/retry.py", line 376, in increment
    raise MaxRetryError(_pool, url, error or ResponseError(cause))
telegram.vendor.ptb_urllib3.urllib3.exceptions.MaxRetryError: HTTPSConnectionPool(host='api.telegram.org', port=443): Max retries exceeded with url: /bot1200188911:AAGUU56MpLmA-uk-HjjrYX-mCuYAptas004/getUpdates (Caused by NewConnectionError('<telegram.vendor.ptb_urllib3.urllib3.connection.VerifiedHTTPSConnection object at 0x7ff8947206d8>: Failed to establish a new connection: [Errno 101] Network is unreachable',))

During handling of the above exception, another exception occurred:

Traceback (most recent call last):
  File "/home/ec2-user/telegram/LAMPA/venv/lib64/python3.6/site-packages/telegram/ext/updater.py", line 380, in _network_loop_retry
    if not action_cb():
  File "/home/ec2-user/telegram/LAMPA/venv/lib64/python3.6/site-packages/telegram/ext/updater.py", line 341, in polling_action_cb
    allowed_updates=allowed_updates)
  File "<decorator-gen-31>", line 2, in get_updates
  File "/home/ec2-user/telegram/LAMPA/venv/lib64/python3.6/site-packages/telegram/bot.py", line 70, in decorator
    result = func(*args, **kwargs)
  File "/home/ec2-user/telegram/LAMPA/venv/lib64/python3.6/site-packages/telegram/bot.py", line 2136, in get_updates
    result = self._request.post(url, data, timeout=float(read_latency) + float(timeout))
  File "/home/ec2-user/telegram/LAMPA/venv/lib64/python3.6/site-packages/telegram/utils/request.py", line 334, in post
    **urlopen_kwargs)
  File "/home/ec2-user/telegram/LAMPA/venv/lib64/python3.6/site-packages/telegram/utils/request.py", line 231, in _request_wrapper
    raise NetworkError('urllib3 HTTPError {0}'.format(error))
telegram.error.NetworkError: urllib3 HTTPError HTTPSConnectionPool(host='api.telegram.org', port=443): Max retries exceeded with url: /bot1200188911:AAGUU56MpLmA-uk-HjjrYX-mCuYAptas004/getUpdates (Caused by NewConnectionError('<telegram.vendor.ptb_urllib3.urllib3.connection.VerifiedHTTPSConnection object at 0x7ff8947206d8>: Failed to establish a new connection: [Errno 101] Network is unreachable',))
2020-05-17 00:00:45,466 - telegram.vendor.ptb_urllib3.urllib3.connectionpool - WARNING - Retrying (Retry(total=2, connect=None, read=None, redirect=None)) after connection broken by 'NewConnectionError('<telegram.vendor.ptb_urllib3.urllib3.connection.VerifiedHTTPSConnection object at 0x7ff894720400>: Failed to establish a new connection: [Errno 101] Network is unreachable',)': /bot1200188911:AAGUU56MpLmA-uk-HjjrYX-mCuYAptas004/getUpdates
2020-05-17 00:00:50,473 - telegram.vendor.ptb_urllib3.urllib3.connectionpool - WARNING - Retrying (Retry(total=1, connect=None, read=None, redirect=None)) after connection broken by 'NewConnectionError('<telegram.vendor.ptb_urllib3.urllib3.connection.VerifiedHTTPSConnection object at 0x7ff8947209b0>: Failed to establish a new connection: [Errno 101] Network is unreachable',)': /bot1200188911:AAGUU56MpLmA-uk-HjjrYX-mCuYAptas004/getUpdates
2020-05-17 00:00:55,479 - telegram.vendor.ptb_urllib3.urllib3.connectionpool - WARNING - Retrying (Retry(total=0, connect=None, read=None, redirect=None)) after connection broken by 'NewConnectionError('<telegram.vendor.ptb_urllib3.urllib3.connection.VerifiedHTTPSConnection object at 0x7ff894720a58>: Failed to establish a new connection: [Errno 101] Network is unreachable',)': /bot1200188911:AAGUU56MpLmA-uk-HjjrYX-mCuYAptas004/getUpdates
2020-05-17 00:01:00,486 - telegram.ext.updater - ERROR - Error while getting Updates: urllib3 HTTPError HTTPSConnectionPool(host='api.telegram.org', port=443): Max retries exceeded with url: /bot1200188911:AAGUU56MpLmA-uk-HjjrYX-mCuYAptas004/getUpdates (Caused by NewConnectionError('<telegram.vendor.ptb_urllib3.urllib3.connection.VerifiedHTTPSConnection object at 0x7ff894720b38>: Failed to establish a new connection: [Errno 101] Network is unreachable',))
2020-05-17 00:01:00,487 - telegram.ext.dispatcher - ERROR - No error handlers are registered, logging exception.
Traceback (most recent call last):
  File "/home/ec2-user/telegram/LAMPA/venv/lib64/python3.6/site-packages/telegram/vendor/ptb_urllib3/urllib3/connection.py", line 141, in _new_conn
    (self.host, self.port), self.timeout, **extra_kw)
  File "/home/ec2-user/telegram/LAMPA/venv/lib64/python3.6/site-packages/telegram/vendor/ptb_urllib3/urllib3/util/connection.py", line 83, in create_connection
    raise err
  File "/home/ec2-user/telegram/LAMPA/venv/lib64/python3.6/site-packages/telegram/vendor/ptb_urllib3/urllib3/util/connection.py", line 73, in create_connection
    sock.connect(sa)
OSError: [Errno 101] Network is unreachable

During handling of the above exception, another exception occurred:

Traceback (most recent call last):
  File "/home/ec2-user/telegram/LAMPA/venv/lib64/python3.6/site-packages/telegram/vendor/ptb_urllib3/urllib3/connectionpool.py", line 617, in urlopen
    chunked=chunked)
  File "/home/ec2-user/telegram/LAMPA/venv/lib64/python3.6/site-packages/telegram/vendor/ptb_urllib3/urllib3/connectionpool.py", line 360, in _make_request
    self._validate_conn(conn)
  File "/home/ec2-user/telegram/LAMPA/venv/lib64/python3.6/site-packages/telegram/vendor/ptb_urllib3/urllib3/connectionpool.py", line 857, in _validate_conn
    super(HTTPSConnectionPool, self)._validate_conn(conn)
  File "/home/ec2-user/telegram/LAMPA/venv/lib64/python3.6/site-packages/telegram/vendor/ptb_urllib3/urllib3/connectionpool.py", line 289, in _validate_conn
    conn.connect()
  File "/home/ec2-user/telegram/LAMPA/venv/lib64/python3.6/site-packages/telegram/vendor/ptb_urllib3/urllib3/connection.py", line 284, in connect
    conn = self._new_conn()
  File "/home/ec2-user/telegram/LAMPA/venv/lib64/python3.6/site-packages/telegram/vendor/ptb_urllib3/urllib3/connection.py", line 150, in _new_conn
    self, "Failed to establish a new connection: %s" % e)
telegram.vendor.ptb_urllib3.urllib3.exceptions.NewConnectionError: <telegram.vendor.ptb_urllib3.urllib3.connection.VerifiedHTTPSConnection object at 0x7ff894720b38>: Failed to establish a new connection: [Errno 101] Network is unreachable

During handling of the above exception, another exception occurred:

Traceback (most recent call last):
  File "/home/ec2-user/telegram/LAMPA/venv/lib64/python3.6/site-packages/telegram/utils/request.py", line 225, in _request_wrapper
    resp = self._con_pool.request(*args, **kwargs)
  File "/home/ec2-user/telegram/LAMPA/venv/lib64/python3.6/site-packages/telegram/vendor/ptb_urllib3/urllib3/request.py", line 70, in request
    **urlopen_kw)
  File "/home/ec2-user/telegram/LAMPA/venv/lib64/python3.6/site-packages/telegram/vendor/ptb_urllib3/urllib3/request.py", line 148, in request_encode_body
    return self.urlopen(method, url, **extra_kw)
  File "/home/ec2-user/telegram/LAMPA/venv/lib64/python3.6/site-packages/telegram/vendor/ptb_urllib3/urllib3/poolmanager.py", line 244, in urlopen
    response = conn.urlopen(method, u.request_uri, **kw)
  File "/home/ec2-user/telegram/LAMPA/venv/lib64/python3.6/site-packages/telegram/vendor/ptb_urllib3/urllib3/connectionpool.py", line 695, in urlopen
    **response_kw)
  File "/home/ec2-user/telegram/LAMPA/venv/lib64/python3.6/site-packages/telegram/vendor/ptb_urllib3/urllib3/connectionpool.py", line 695, in urlopen
    **response_kw)
  File "/home/ec2-user/telegram/LAMPA/venv/lib64/python3.6/site-packages/telegram/vendor/ptb_urllib3/urllib3/connectionpool.py", line 695, in urlopen
    **response_kw)
  File "/home/ec2-user/telegram/LAMPA/venv/lib64/python3.6/site-packages/telegram/vendor/ptb_urllib3/urllib3/connectionpool.py", line 666, in urlopen
    _stacktrace=sys.exc_info()[2])
  File "/home/ec2-user/telegram/LAMPA/venv/lib64/python3.6/site-packages/telegram/vendor/ptb_urllib3/urllib3/util/retry.py", line 376, in increment
    raise MaxRetryError(_pool, url, error or ResponseError(cause))
telegram.vendor.ptb_urllib3.urllib3.exceptions.MaxRetryError: HTTPSConnectionPool(host='api.telegram.org', port=443): Max retries exceeded with url: /bot1200188911:AAGUU56MpLmA-uk-HjjrYX-mCuYAptas004/getUpdates (Caused by NewConnectionError('<telegram.vendor.ptb_urllib3.urllib3.connection.VerifiedHTTPSConnection object at 0x7ff894720b38>: Failed to establish a new connection: [Errno 101] Network is unreachable',))

During handling of the above exception, another exception occurred:

Traceback (most recent call last):
  File "/home/ec2-user/telegram/LAMPA/venv/lib64/python3.6/site-packages/telegram/ext/updater.py", line 380, in _network_loop_retry
    if not action_cb():
  File "/home/ec2-user/telegram/LAMPA/venv/lib64/python3.6/site-packages/telegram/ext/updater.py", line 341, in polling_action_cb
    allowed_updates=allowed_updates)
  File "<decorator-gen-31>", line 2, in get_updates
  File "/home/ec2-user/telegram/LAMPA/venv/lib64/python3.6/site-packages/telegram/bot.py", line 70, in decorator
    result = func(*args, **kwargs)
  File "/home/ec2-user/telegram/LAMPA/venv/lib64/python3.6/site-packages/telegram/bot.py", line 2136, in get_updates
    result = self._request.post(url, data, timeout=float(read_latency) + float(timeout))
  File "/home/ec2-user/telegram/LAMPA/venv/lib64/python3.6/site-packages/telegram/utils/request.py", line 334, in post
    **urlopen_kwargs)
  File "/home/ec2-user/telegram/LAMPA/venv/lib64/python3.6/site-packages/telegram/utils/request.py", line 231, in _request_wrapper
    raise NetworkError('urllib3 HTTPError {0}'.format(error))
telegram.error.NetworkError: urllib3 HTTPError HTTPSConnectionPool(host='api.telegram.org', port=443): Max retries exceeded with url: /bot1200188911:AAGUU56MpLmA-uk-HjjrYX-mCuYAptas004/getUpdates (Caused by NewConnectionError('<telegram.vendor.ptb_urllib3.urllib3.connection.VerifiedHTTPSConnection object at 0x7ff894720b38>: Failed to establish a new connection: [Errno 101] Network is unreachable',))
2020-05-17 00:01:13,095 - telegram.vendor.ptb_urllib3.urllib3.connectionpool - WARNING - Retrying (Retry(total=2, connect=None, read=None, redirect=None)) after connection broken by 'NewConnectionError('<telegram.vendor.ptb_urllib3.urllib3.connection.VerifiedHTTPSConnection object at 0x7ff8967f7da0>: Failed to establish a new connection: [Errno 101] Network is unreachable',)': /bot1200188911:AAGUU56MpLmA-uk-HjjrYX-mCuYAptas004/getUpdates
2020-05-17 00:01:18,101 - telegram.vendor.ptb_urllib3.urllib3.connectionpool - WARNING - Retrying (Retry(total=1, connect=None, read=None, redirect=None)) after connection broken by 'NewConnectionError('<telegram.vendor.ptb_urllib3.urllib3.connection.VerifiedHTTPSConnection object at 0x7ff8967f7cf8>: Failed to establish a new connection: [Errno 101] Network is unreachable',)': /bot1200188911:AAGUU56MpLmA-uk-HjjrYX-mCuYAptas004/getUpdates
2020-05-17 00:01:23,108 - telegram.vendor.ptb_urllib3.urllib3.connectionpool - WARNING - Retrying (Retry(total=0, connect=None, read=None, redirect=None)) after connection broken by 'NewConnectionError('<telegram.vendor.ptb_urllib3.urllib3.connection.VerifiedHTTPSConnection object at 0x7ff8967f7c50>: Failed to establish a new connection: [Errno 101] Network is unreachable',)': /bot1200188911:AAGUU56MpLmA-uk-HjjrYX-mCuYAptas004/getUpdates
2020-05-17 00:01:28,115 - telegram.ext.updater - ERROR - Error while getting Updates: urllib3 HTTPError HTTPSConnectionPool(host='api.telegram.org', port=443): Max retries exceeded with url: /bot1200188911:AAGUU56MpLmA-uk-HjjrYX-mCuYAptas004/getUpdates (Caused by NewConnectionError('<telegram.vendor.ptb_urllib3.urllib3.connection.VerifiedHTTPSConnection object at 0x7ff8967f7358>: Failed to establish a new connection: [Errno 101] Network is unreachable',))
2020-05-17 00:01:28,115 - telegram.ext.dispatcher - ERROR - No error handlers are registered, logging exception.
Traceback (most recent call last):
  File "/home/ec2-user/telegram/LAMPA/venv/lib64/python3.6/site-packages/telegram/vendor/ptb_urllib3/urllib3/connection.py", line 141, in _new_conn
    (self.host, self.port), self.timeout, **extra_kw)
  File "/home/ec2-user/telegram/LAMPA/venv/lib64/python3.6/site-packages/telegram/vendor/ptb_urllib3/urllib3/util/connection.py", line 83, in create_connection
    raise err
  File "/home/ec2-user/telegram/LAMPA/venv/lib64/python3.6/site-packages/telegram/vendor/ptb_urllib3/urllib3/util/connection.py", line 73, in create_connection
    sock.connect(sa)
OSError: [Errno 101] Network is unreachable

During handling of the above exception, another exception occurred:

Traceback (most recent call last):
  File "/home/ec2-user/telegram/LAMPA/venv/lib64/python3.6/site-packages/telegram/vendor/ptb_urllib3/urllib3/connectionpool.py", line 617, in urlopen
    chunked=chunked)
  File "/home/ec2-user/telegram/LAMPA/venv/lib64/python3.6/site-packages/telegram/vendor/ptb_urllib3/urllib3/connectionpool.py", line 360, in _make_request
    self._validate_conn(conn)
  File "/home/ec2-user/telegram/LAMPA/venv/lib64/python3.6/site-packages/telegram/vendor/ptb_urllib3/urllib3/connectionpool.py", line 857, in _validate_conn
    super(HTTPSConnectionPool, self)._validate_conn(conn)
  File "/home/ec2-user/telegram/LAMPA/venv/lib64/python3.6/site-packages/telegram/vendor/ptb_urllib3/urllib3/connectionpool.py", line 289, in _validate_conn
    conn.connect()
  File "/home/ec2-user/telegram/LAMPA/venv/lib64/python3.6/site-packages/telegram/vendor/ptb_urllib3/urllib3/connection.py", line 284, in connect
    conn = self._new_conn()
  File "/home/ec2-user/telegram/LAMPA/venv/lib64/python3.6/site-packages/telegram/vendor/ptb_urllib3/urllib3/connection.py", line 150, in _new_conn
    self, "Failed to establish a new connection: %s" % e)
telegram.vendor.ptb_urllib3.urllib3.exceptions.NewConnectionError: <telegram.vendor.ptb_urllib3.urllib3.connection.VerifiedHTTPSConnection object at 0x7ff8967f7358>: Failed to establish a new connection: [Errno 101] Network is unreachable

During handling of the above exception, another exception occurred:

Traceback (most recent call last):
  File "/home/ec2-user/telegram/LAMPA/venv/lib64/python3.6/site-packages/telegram/utils/request.py", line 225, in _request_wrapper
    resp = self._con_pool.request(*args, **kwargs)
  File "/home/ec2-user/telegram/LAMPA/venv/lib64/python3.6/site-packages/telegram/vendor/ptb_urllib3/urllib3/request.py", line 70, in request
    **urlopen_kw)
  File "/home/ec2-user/telegram/LAMPA/venv/lib64/python3.6/site-packages/telegram/vendor/ptb_urllib3/urllib3/request.py", line 148, in request_encode_body
    return self.urlopen(method, url, **extra_kw)
  File "/home/ec2-user/telegram/LAMPA/venv/lib64/python3.6/site-packages/telegram/vendor/ptb_urllib3/urllib3/poolmanager.py", line 244, in urlopen
    response = conn.urlopen(method, u.request_uri, **kw)
  File "/home/ec2-user/telegram/LAMPA/venv/lib64/python3.6/site-packages/telegram/vendor/ptb_urllib3/urllib3/connectionpool.py", line 695, in urlopen
    **response_kw)
  File "/home/ec2-user/telegram/LAMPA/venv/lib64/python3.6/site-packages/telegram/vendor/ptb_urllib3/urllib3/connectionpool.py", line 695, in urlopen
    **response_kw)
  File "/home/ec2-user/telegram/LAMPA/venv/lib64/python3.6/site-packages/telegram/vendor/ptb_urllib3/urllib3/connectionpool.py", line 695, in urlopen
    **response_kw)
  File "/home/ec2-user/telegram/LAMPA/venv/lib64/python3.6/site-packages/telegram/vendor/ptb_urllib3/urllib3/connectionpool.py", line 666, in urlopen
    _stacktrace=sys.exc_info()[2])
  File "/home/ec2-user/telegram/LAMPA/venv/lib64/python3.6/site-packages/telegram/vendor/ptb_urllib3/urllib3/util/retry.py", line 376, in increment
    raise MaxRetryError(_pool, url, error or ResponseError(cause))
telegram.vendor.ptb_urllib3.urllib3.exceptions.MaxRetryError: HTTPSConnectionPool(host='api.telegram.org', port=443): Max retries exceeded with url: /bot1200188911:AAGUU56MpLmA-uk-HjjrYX-mCuYAptas004/getUpdates (Caused by NewConnectionError('<telegram.vendor.ptb_urllib3.urllib3.connection.VerifiedHTTPSConnection object at 0x7ff8967f7358>: Failed to establish a new connection: [Errno 101] Network is unreachable',))

During handling of the above exception, another exception occurred:

Traceback (most recent call last):
  File "/home/ec2-user/telegram/LAMPA/venv/lib64/python3.6/site-packages/telegram/ext/updater.py", line 380, in _network_loop_retry
    if not action_cb():
  File "/home/ec2-user/telegram/LAMPA/venv/lib64/python3.6/site-packages/telegram/ext/updater.py", line 341, in polling_action_cb
    allowed_updates=allowed_updates)
  File "<decorator-gen-31>", line 2, in get_updates
  File "/home/ec2-user/telegram/LAMPA/venv/lib64/python3.6/site-packages/telegram/bot.py", line 70, in decorator
    result = func(*args, **kwargs)
  File "/home/ec2-user/telegram/LAMPA/venv/lib64/python3.6/site-packages/telegram/bot.py", line 2136, in get_updates
    result = self._request.post(url, data, timeout=float(read_latency) + float(timeout))
  File "/home/ec2-user/telegram/LAMPA/venv/lib64/python3.6/site-packages/telegram/utils/request.py", line 334, in post
    **urlopen_kwargs)
  File "/home/ec2-user/telegram/LAMPA/venv/lib64/python3.6/site-packages/telegram/utils/request.py", line 231, in _request_wrapper
    raise NetworkError('urllib3 HTTPError {0}'.format(error))
telegram.error.NetworkError: urllib3 HTTPError HTTPSConnectionPool(host='api.telegram.org', port=443): Max retries exceeded with url: /bot1200188911:AAGUU56MpLmA-uk-HjjrYX-mCuYAptas004/getUpdates (Caused by NewConnectionError('<telegram.vendor.ptb_urllib3.urllib3.connection.VerifiedHTTPSConnection object at 0x7ff8967f7358>: Failed to establish a new connection: [Errno 101] Network is unreachable',))
2020-05-17 00:01:44,522 - telegram.vendor.ptb_urllib3.urllib3.connectionpool - WARNING - Retrying (Retry(total=2, connect=None, read=None, redirect=None)) after connection broken by 'NewConnectionError('<telegram.vendor.ptb_urllib3.urllib3.connection.VerifiedHTTPSConnection object at 0x7ff8967f7eb8>: Failed to establish a new connection: [Errno 101] Network is unreachable',)': /bot1200188911:AAGUU56MpLmA-uk-HjjrYX-mCuYAptas004/getUpdates
2020-05-17 00:01:49,526 - telegram.vendor.ptb_urllib3.urllib3.connectionpool - WARNING - Retrying (Retry(total=1, connect=None, read=None, redirect=None)) after connection broken by 'NewConnectionError('<telegram.vendor.ptb_urllib3.urllib3.connection.VerifiedHTTPSConnection object at 0x7ff896c56f60>: Failed to establish a new connection: [Errno 101] Network is unreachable',)': /bot1200188911:AAGUU56MpLmA-uk-HjjrYX-mCuYAptas004/getUpdates
2020-05-17 00:01:54,533 - telegram.vendor.ptb_urllib3.urllib3.connectionpool - WARNING - Retrying (Retry(total=0, connect=None, read=None, redirect=None)) after connection broken by 'NewConnectionError('<telegram.vendor.ptb_urllib3.urllib3.connection.VerifiedHTTPSConnection object at 0x7ff8947207f0>: Failed to establish a new connection: [Errno 101] Network is unreachable',)': /bot1200188911:AAGUU56MpLmA-uk-HjjrYX-mCuYAptas004/getUpdates
2020-05-17 00:01:59,541 - telegram.ext.updater - ERROR - Error while getting Updates: urllib3 HTTPError HTTPSConnectionPool(host='api.telegram.org', port=443): Max retries exceeded with url: /bot1200188911:AAGUU56MpLmA-uk-HjjrYX-mCuYAptas004/getUpdates (Caused by NewConnectionError('<telegram.vendor.ptb_urllib3.urllib3.connection.VerifiedHTTPSConnection object at 0x7ff894720be0>: Failed to establish a new connection: [Errno 101] Network is unreachable',))
2020-05-17 00:01:59,541 - telegram.ext.dispatcher - ERROR - No error handlers are registered, logging exception.
Traceback (most recent call last):
  File "/home/ec2-user/telegram/LAMPA/venv/lib64/python3.6/site-packages/telegram/vendor/ptb_urllib3/urllib3/connection.py", line 141, in _new_conn
    (self.host, self.port), self.timeout, **extra_kw)
  File "/home/ec2-user/telegram/LAMPA/venv/lib64/python3.6/site-packages/telegram/vendor/ptb_urllib3/urllib3/util/connection.py", line 83, in create_connection
    raise err
  File "/home/ec2-user/telegram/LAMPA/venv/lib64/python3.6/site-packages/telegram/vendor/ptb_urllib3/urllib3/util/connection.py", line 73, in create_connection
    sock.connect(sa)
OSError: [Errno 101] Network is unreachable

During handling of the above exception, another exception occurred:

Traceback (most recent call last):
  File "/home/ec2-user/telegram/LAMPA/venv/lib64/python3.6/site-packages/telegram/vendor/ptb_urllib3/urllib3/connectionpool.py", line 617, in urlopen
    chunked=chunked)
  File "/home/ec2-user/telegram/LAMPA/venv/lib64/python3.6/site-packages/telegram/vendor/ptb_urllib3/urllib3/connectionpool.py", line 360, in _make_request
    self._validate_conn(conn)
  File "/home/ec2-user/telegram/LAMPA/venv/lib64/python3.6/site-packages/telegram/vendor/ptb_urllib3/urllib3/connectionpool.py", line 857, in _validate_conn
    super(HTTPSConnectionPool, self)._validate_conn(conn)
  File "/home/ec2-user/telegram/LAMPA/venv/lib64/python3.6/site-packages/telegram/vendor/ptb_urllib3/urllib3/connectionpool.py", line 289, in _validate_conn
    conn.connect()
  File "/home/ec2-user/telegram/LAMPA/venv/lib64/python3.6/site-packages/telegram/vendor/ptb_urllib3/urllib3/connection.py", line 284, in connect
    conn = self._new_conn()
  File "/home/ec2-user/telegram/LAMPA/venv/lib64/python3.6/site-packages/telegram/vendor/ptb_urllib3/urllib3/connection.py", line 150, in _new_conn
    self, "Failed to establish a new connection: %s" % e)
telegram.vendor.ptb_urllib3.urllib3.exceptions.NewConnectionError: <telegram.vendor.ptb_urllib3.urllib3.connection.VerifiedHTTPSConnection object at 0x7ff894720be0>: Failed to establish a new connection: [Errno 101] Network is unreachable

During handling of the above exception, another exception occurred:

Traceback (most recent call last):
  File "/home/ec2-user/telegram/LAMPA/venv/lib64/python3.6/site-packages/telegram/utils/request.py", line 225, in _request_wrapper
    resp = self._con_pool.request(*args, **kwargs)
  File "/home/ec2-user/telegram/LAMPA/venv/lib64/python3.6/site-packages/telegram/vendor/ptb_urllib3/urllib3/request.py", line 70, in request
    **urlopen_kw)
  File "/home/ec2-user/telegram/LAMPA/venv/lib64/python3.6/site-packages/telegram/vendor/ptb_urllib3/urllib3/request.py", line 148, in request_encode_body
    return self.urlopen(method, url, **extra_kw)
  File "/home/ec2-user/telegram/LAMPA/venv/lib64/python3.6/site-packages/telegram/vendor/ptb_urllib3/urllib3/poolmanager.py", line 244, in urlopen
    response = conn.urlopen(method, u.request_uri, **kw)
  File "/home/ec2-user/telegram/LAMPA/venv/lib64/python3.6/site-packages/telegram/vendor/ptb_urllib3/urllib3/connectionpool.py", line 695, in urlopen
    **response_kw)
  File "/home/ec2-user/telegram/LAMPA/venv/lib64/python3.6/site-packages/telegram/vendor/ptb_urllib3/urllib3/connectionpool.py", line 695, in urlopen
    **response_kw)
  File "/home/ec2-user/telegram/LAMPA/venv/lib64/python3.6/site-packages/telegram/vendor/ptb_urllib3/urllib3/connectionpool.py", line 695, in urlopen
    **response_kw)
  File "/home/ec2-user/telegram/LAMPA/venv/lib64/python3.6/site-packages/telegram/vendor/ptb_urllib3/urllib3/connectionpool.py", line 666, in urlopen
    _stacktrace=sys.exc_info()[2])
  File "/home/ec2-user/telegram/LAMPA/venv/lib64/python3.6/site-packages/telegram/vendor/ptb_urllib3/urllib3/util/retry.py", line 376, in increment
    raise MaxRetryError(_pool, url, error or ResponseError(cause))
telegram.vendor.ptb_urllib3.urllib3.exceptions.MaxRetryError: HTTPSConnectionPool(host='api.telegram.org', port=443): Max retries exceeded with url: /bot1200188911:AAGUU56MpLmA-uk-HjjrYX-mCuYAptas004/getUpdates (Caused by NewConnectionError('<telegram.vendor.ptb_urllib3.urllib3.connection.VerifiedHTTPSConnection object at 0x7ff894720be0>: Failed to establish a new connection: [Errno 101] Network is unreachable',))

During handling of the above exception, another exception occurred:

Traceback (most recent call last):
  File "/home/ec2-user/telegram/LAMPA/venv/lib64/python3.6/site-packages/telegram/ext/updater.py", line 380, in _network_loop_retry
    if not action_cb():
  File "/home/ec2-user/telegram/LAMPA/venv/lib64/python3.6/site-packages/telegram/ext/updater.py", line 341, in polling_action_cb
    allowed_updates=allowed_updates)
  File "<decorator-gen-31>", line 2, in get_updates
  File "/home/ec2-user/telegram/LAMPA/venv/lib64/python3.6/site-packages/telegram/bot.py", line 70, in decorator
    result = func(*args, **kwargs)
  File "/home/ec2-user/telegram/LAMPA/venv/lib64/python3.6/site-packages/telegram/bot.py", line 2136, in get_updates
    result = self._request.post(url, data, timeout=float(read_latency) + float(timeout))
  File "/home/ec2-user/telegram/LAMPA/venv/lib64/python3.6/site-packages/telegram/utils/request.py", line 334, in post
    **urlopen_kwargs)
  File "/home/ec2-user/telegram/LAMPA/venv/lib64/python3.6/site-packages/telegram/utils/request.py", line 231, in _request_wrapper
    raise NetworkError('urllib3 HTTPError {0}'.format(error))
telegram.error.NetworkError: urllib3 HTTPError HTTPSConnectionPool(host='api.telegram.org', port=443): Max retries exceeded with url: /bot1200188911:AAGUU56MpLmA-uk-HjjrYX-mCuYAptas004/getUpdates (Caused by NewConnectionError('<telegram.vendor.ptb_urllib3.urllib3.connection.VerifiedHTTPSConnection object at 0x7ff894720be0>: Failed to establish a new connection: [Errno 101] Network is unreachable',))
2020-05-17 00:02:21,652 - telegram.vendor.ptb_urllib3.urllib3.connectionpool - WARNING - Retrying (Retry(total=2, connect=None, read=None, redirect=None)) after connection broken by 'NewConnectionError('<telegram.vendor.ptb_urllib3.urllib3.connection.VerifiedHTTPSConnection object at 0x7ff894720208>: Failed to establish a new connection: [Errno 101] Network is unreachable',)': /bot1200188911:AAGUU56MpLmA-uk-HjjrYX-mCuYAptas004/getUpdates
2020-05-17 06:54:13,756 - conversation.handlers - INFO - User 259625668: press /start;
2020-05-17 06:54:17,434 - conversation.handlers - INFO - User 259625668: fruit func;
2020-05-17 06:54:21,300 - conversation.handlers - INFO - User 259625668: sound func;
2020-05-17 06:54:41,043 - conversation.handlers - INFO - User 259625668: animal func;
2020-05-17 06:54:47,292 - conversation.handlers - INFO - User 259625668: stickers func;
2020-05-17 06:54:52,165 - conversation.handlers - INFO - User 259625668: stickers_yes func;
2020-05-17 06:54:52,386 - conversation.handlers - INFO - User 259625668: consent func;
2020-05-17 06:55:00,450 - telegram.ext.dispatcher - ERROR - No error handlers are registered, logging exception.
Traceback (most recent call last):
  File "/home/ec2-user/telegram/LAMPA/venv/lib64/python3.6/site-packages/telegram/ext/dispatcher.py", line 343, in process_update
    handler.handle_update(update, self, check, context)
  File "/home/ec2-user/telegram/LAMPA/venv/lib64/python3.6/site-packages/telegram/ext/conversationhandler.py", line 465, in handle_update
    new_state = handler.handle_update(update, dispatcher, check_result, context)
  File "/home/ec2-user/telegram/LAMPA/venv/lib64/python3.6/site-packages/telegram/ext/conversationhandler.py", line 465, in handle_update
    new_state = handler.handle_update(update, dispatcher, check_result, context)
  File "/home/ec2-user/telegram/LAMPA/venv/lib64/python3.6/site-packages/telegram/ext/handler.py", line 119, in handle_update
    return self.callback(update, context)
  File "/home/ec2-user/telegram/LAMPA/lampa-bot/conversation/chat.py", line 34, in start
    context.bot.send_message(chat_id=users[update.message.chat_id], text=msg_text)
  File "<decorator-gen-2>", line 2, in send_message
  File "/home/ec2-user/telegram/LAMPA/venv/lib64/python3.6/site-packages/telegram/bot.py", line 70, in decorator
    result = func(*args, **kwargs)
  File "/home/ec2-user/telegram/LAMPA/venv/lib64/python3.6/site-packages/telegram/bot.py", line 351, in send_message
    timeout=timeout, **kwargs)
  File "/home/ec2-user/telegram/LAMPA/venv/lib64/python3.6/site-packages/telegram/bot.py", line 178, in _message
    result = self._request.post(url, data, timeout=timeout)
  File "/home/ec2-user/telegram/LAMPA/venv/lib64/python3.6/site-packages/telegram/utils/request.py", line 334, in post
    **urlopen_kwargs)
  File "/home/ec2-user/telegram/LAMPA/venv/lib64/python3.6/site-packages/telegram/utils/request.py", line 243, in _request_wrapper
    raise Unauthorized(message)
telegram.error.Unauthorized: Forbidden: bot was blocked by the user
2020-05-17 10:43:11,524 - conversation.handlers - INFO - User 384341805: press /start;
2020-05-17 10:43:13,962 - conversation.handlers - INFO - User 384341805: fruit func;
2020-05-17 10:43:15,123 - conversation.handlers - INFO - User 384341805: sound func;
2020-05-17 10:43:15,956 - conversation.handlers - INFO - User 384341805: animal func;
2020-05-17 10:43:16,640 - conversation.handlers - INFO - User 384341805: stickers func;
2020-05-17 10:43:16,757 - conversation.handlers - INFO - User 384341805: consent func;
2020-05-17 10:43:21,806 - conversation.handlers - INFO - User 384341805: current_mood func;
2020-05-17 10:43:24,334 - conversation.handlers - INFO - User 384341805: press /start;
2020-05-17 11:40:49,160 - conversation.handlers - INFO - User 1055690376: press /start;
2020-05-17 11:40:50,756 - conversation.handlers - INFO - User 1055690376: fruit func;
2020-05-17 11:40:51,984 - conversation.handlers - INFO - User 1055690376: sound func;
2020-05-17 11:40:54,791 - conversation.handlers - INFO - User 1055690376: animal func;
2020-05-17 11:41:00,479 - conversation.handlers - INFO - User 1055690376: stickers func;
2020-05-17 11:41:00,629 - conversation.handlers - INFO - User 1055690376: consent func;
2020-05-17 12:07:19,539 - conversation.handlers - INFO - User 383327735: press /start;
2020-05-17 12:07:20,750 - conversation.handlers - INFO - User 383327735: fruit func;
2020-05-17 12:42:34,388 - conversation.handlers - INFO - User 383327735: sound func;
2020-05-17 12:42:35,658 - conversation.handlers - INFO - User 383327735: animal func;
2020-05-17 12:54:13,083 - conversation.handlers - INFO - User 68758887: press /start;
2020-05-17 12:54:14,807 - conversation.handlers - INFO - User 68758887: fruit func;
2020-05-17 12:54:16,125 - conversation.handlers - INFO - User 68758887: sound func;
2020-05-17 12:54:16,834 - conversation.handlers - INFO - User 68758887: animal func;
2020-05-17 12:54:17,317 - conversation.handlers - INFO - User 68758887: stickers func;
2020-05-17 12:54:17,438 - conversation.handlers - INFO - User 68758887: consent func;
2020-05-17 12:59:06,660 - conversation.handlers - INFO - User 68758887: current_mood func;
2020-05-17 12:59:11,810 - conversation.handlers - INFO - User 68758887: press /start;
2020-05-17 16:02:01,478 - conversation.handlers - INFO - User 211241527: press /start;
2020-05-17 16:02:03,584 - conversation.handlers - INFO - User 211241527: fruit func;
2020-05-17 16:02:07,533 - conversation.handlers - INFO - User 211241527: sound func;
2020-05-17 16:02:14,997 - conversation.handlers - INFO - User 211241527: animal func;
2020-05-17 16:02:18,784 - conversation.handlers - INFO - User 211241527: stickers func;
2020-05-17 16:02:24,319 - conversation.handlers - INFO - User 211241527: stickers_yes func;
2020-05-17 16:02:24,455 - conversation.handlers - INFO - User 211241527: consent func;
2020-05-17 16:06:18,285 - conversation.handlers - INFO - User 142443248: press /start;
2020-05-17 16:06:20,556 - conversation.handlers - INFO - User 142443248: fruit func;
2020-05-17 16:06:24,135 - conversation.handlers - INFO - User 142443248: sound func;
2020-05-17 16:06:26,386 - conversation.handlers - INFO - User 142443248: animal func;
2020-05-17 16:06:31,978 - conversation.handlers - INFO - User 142443248: stickers func;
2020-05-17 16:06:32,109 - conversation.handlers - INFO - User 142443248: consent func;
2020-05-17 16:14:19,018 - telegram.ext.dispatcher - ERROR - No error handlers are registered, logging exception.
Traceback (most recent call last):
  File "/home/ec2-user/telegram/LAMPA/venv/lib64/python3.6/site-packages/telegram/ext/dispatcher.py", line 343, in process_update
    handler.handle_update(update, self, check, context)
  File "/home/ec2-user/telegram/LAMPA/venv/lib64/python3.6/site-packages/telegram/ext/conversationhandler.py", line 465, in handle_update
    new_state = handler.handle_update(update, dispatcher, check_result, context)
  File "/home/ec2-user/telegram/LAMPA/venv/lib64/python3.6/site-packages/telegram/ext/conversationhandler.py", line 465, in handle_update
    new_state = handler.handle_update(update, dispatcher, check_result, context)
  File "/home/ec2-user/telegram/LAMPA/venv/lib64/python3.6/site-packages/telegram/ext/handler.py", line 119, in handle_update
    return self.callback(update, context)
  File "/home/ec2-user/telegram/LAMPA/lampa-bot/conversation/chat.py", line 50, in answer
    chat_id = update.message.chat.id or update.message.chat_id
AttributeError: 'NoneType' object has no attribute 'chat'
2020-05-17 17:20:21,944 - conversation.handlers - INFO - User 1055690376: current_mood func;
2020-05-17 17:20:24,766 - conversation.handlers - INFO - User 1055690376: press /start;
2020-05-17 17:20:30,203 - conversation.payment - INFO - User 1055690376: try to subscribe;
2020-05-17 17:20:39,843 - conversation.handlers - INFO - User 1055690376: press /start;
2020-05-17 17:54:55,414 - conversation.handlers - INFO - User 384341805: fruit func;
2020-05-17 17:54:56,335 - conversation.handlers - INFO - User 384341805: sound func;
2020-05-17 17:54:57,418 - conversation.handlers - INFO - User 384341805: animal func;
2020-05-17 17:54:58,067 - conversation.handlers - INFO - User 384341805: stickers func;
2020-05-17 17:54:58,197 - conversation.handlers - INFO - User 384341805: consent func;
2020-05-17 17:55:03,809 - conversation.handlers - INFO - User 384341805: current_mood func;
2020-05-17 17:55:06,745 - conversation.handlers - INFO - User 384341805: press /start;
2020-05-17 17:56:33,328 - conversation.handlers - INFO - User 35769592: press /start;
2020-05-17 17:56:34,913 - conversation.handlers - INFO - User 35769592: fruit func;
2020-05-17 17:56:37,302 - conversation.handlers - INFO - User 35769592: sound func;
2020-05-17 17:56:39,749 - conversation.handlers - INFO - User 35769592: animal func;
2020-05-17 17:56:43,069 - conversation.handlers - INFO - User 35769592: stickers func;
2020-05-17 17:56:43,196 - conversation.handlers - INFO - User 35769592: consent func;
2020-05-17 19:08:00,020 - conversation.handlers - INFO - User 211241527: current_mood func;
2020-05-17 19:08:14,990 - conversation.handlers - INFO - User 211241527: press /start;
2020-05-17 19:28:35,546 - conversation.handlers - INFO - User 211241527: fruit func;
2020-05-17 19:28:38,115 - conversation.handlers - INFO - User 211241527: sound func;
2020-05-17 19:28:45,783 - conversation.handlers - INFO - User 211241527: animal func;
2020-05-17 19:28:48,066 - conversation.handlers - INFO - User 211241527: stickers func;
2020-05-17 19:28:48,262 - conversation.handlers - INFO - User 211241527: consent func;
2020-05-17 19:30:23,921 - telegram.ext.dispatcher - ERROR - No error handlers are registered, logging exception.
Traceback (most recent call last):
  File "/home/ec2-user/telegram/LAMPA/venv/lib64/python3.6/site-packages/telegram/ext/dispatcher.py", line 343, in process_update
    handler.handle_update(update, self, check, context)
  File "/home/ec2-user/telegram/LAMPA/venv/lib64/python3.6/site-packages/telegram/ext/conversationhandler.py", line 465, in handle_update
    new_state = handler.handle_update(update, dispatcher, check_result, context)
  File "/home/ec2-user/telegram/LAMPA/venv/lib64/python3.6/site-packages/telegram/ext/conversationhandler.py", line 465, in handle_update
    new_state = handler.handle_update(update, dispatcher, check_result, context)
  File "/home/ec2-user/telegram/LAMPA/venv/lib64/python3.6/site-packages/telegram/ext/handler.py", line 119, in handle_update
    return self.callback(update, context)
  File "/home/ec2-user/telegram/LAMPA/lampa-bot/conversation/chat.py", line 50, in answer
    chat_id = update.message.chat.id or update.message.chat_id
AttributeError: 'NoneType' object has no attribute 'chat'
2020-05-17 19:30:44,375 - telegram.ext.dispatcher - ERROR - No error handlers are registered, logging exception.
Traceback (most recent call last):
  File "/home/ec2-user/telegram/LAMPA/venv/lib64/python3.6/site-packages/telegram/ext/dispatcher.py", line 343, in process_update
    handler.handle_update(update, self, check, context)
  File "/home/ec2-user/telegram/LAMPA/venv/lib64/python3.6/site-packages/telegram/ext/conversationhandler.py", line 465, in handle_update
    new_state = handler.handle_update(update, dispatcher, check_result, context)
  File "/home/ec2-user/telegram/LAMPA/venv/lib64/python3.6/site-packages/telegram/ext/conversationhandler.py", line 465, in handle_update
    new_state = handler.handle_update(update, dispatcher, check_result, context)
  File "/home/ec2-user/telegram/LAMPA/venv/lib64/python3.6/site-packages/telegram/ext/handler.py", line 119, in handle_update
    return self.callback(update, context)
  File "/home/ec2-user/telegram/LAMPA/lampa-bot/conversation/chat.py", line 50, in answer
    chat_id = update.message.chat.id or update.message.chat_id
AttributeError: 'NoneType' object has no attribute 'chat'
2020-05-17 19:31:15,294 - conversation.handlers - INFO - User 211241527: current_mood func;
2020-05-17 19:31:21,152 - conversation.handlers - INFO - User 211241527: press /start;
2020-05-17 19:31:23,230 - conversation.handlers - INFO - User 211241527: fruit func;
2020-05-17 19:31:24,975 - conversation.handlers - INFO - User 211241527: sound func;
2020-05-17 19:31:28,423 - conversation.handlers - INFO - User 211241527: animal func;
2020-05-17 19:31:31,376 - conversation.handlers - INFO - User 211241527: stickers func;
2020-05-17 19:31:31,495 - conversation.handlers - INFO - User 211241527: consent func;
2020-05-17 19:32:25,132 - telegram.ext.updater - INFO - Received signal 15 (SIGTERM), stopping...
Database exist
.env exist
Starting
Started succesfully
[220728253]
{220728253: 259625668, 259625668: 220728253} []
[384341805]
{220728253: 259625668, 259625668: 220728253} []
[1055690376]
{220728253: 259625668, 259625668: 220728253} [1055690376]
[]
{220728253: 259625668, 259625668: 220728253} []
[211241527]
[]
{220728253: 259625668, 259625668: 220728253, 211241527: 142443248, 142443248: 211241527} []
[384341805]
{220728253: 259625668, 259625668: 220728253, 211241527: 142443248, 142443248: 211241527} []
{220728253: 259625668, 259625668: 220728253, 211241527: 142443248, 142443248: 211241527} []
{220728253: 259625668, 259625668: 220728253, 211241527: 142443248, 142443248: 211241527} []
[35769592]
{220728253: 259625668, 259625668: 220728253} [35769592]
[]
{220728253: 259625668, 259625668: 220728253} []
{220728253: 259625668, 259625668: 220728253} []
[211241527]
/home/ec2-user/telegram/LAMPA/venv/lib64/python3.6/site-packages/telegram/ext/conversationhandler.py:220: UserWarning: If 'per_message=False', 'CallbackQueryHandler' will not be tracked for every message.
  warnings.warn("If 'per_message=False', 'CallbackQueryHandler' will not be "
2020-05-17 20:23:45,287 - conversation.handlers - INFO - User 383327735: press /start;
2020-05-17 20:28:16,982 - matplotlib.category - INFO - Using categorical units to plot a list of strings that are all parsable as floats or dates. If these strings should be plotted as numbers, cast to the appropriate data type before plotting.
2020-05-17 20:28:16,984 - matplotlib.category - INFO - Using categorical units to plot a list of strings that are all parsable as floats or dates. If these strings should be plotted as numbers, cast to the appropriate data type before plotting.
2020-05-17 20:28:36,551 - conversation.handlers - INFO - User 68758887: press /start;
2020-05-17 20:28:42,875 - matplotlib.category - INFO - Using categorical units to plot a list of strings that are all parsable as floats or dates. If these strings should be plotted as numbers, cast to the appropriate data type before plotting.
2020-05-17 20:28:42,877 - matplotlib.category - INFO - Using categorical units to plot a list of strings that are all parsable as floats or dates. If these strings should be plotted as numbers, cast to the appropriate data type before plotting.
2020-05-17 21:20:45,753 - conversation.handlers - INFO - User 42303979: press /start;
2020-05-17 21:20:48,427 - conversation.handlers - INFO - User 42303979: fruit func;
2020-05-17 21:20:56,963 - conversation.handlers - INFO - User 42303979: sound func;
2020-05-17 21:21:02,287 - conversation.handlers - INFO - User 42303979: animal func;
2020-05-17 21:21:08,105 - conversation.handlers - INFO - User 42303979: stickers func;
2020-05-17 21:21:11,245 - conversation.handlers - INFO - User 42303979: stickers_no func;
2020-05-17 21:21:11,366 - conversation.handlers - INFO - User 42303979: consent func;
2020-05-17 23:07:17,180 - conversation.handlers - INFO - User 381283937: press /start;
2020-05-17 23:07:17,916 - conversation.handlers - INFO - User 381283937: fruit func;
2020-05-17 23:07:28,996 - conversation.handlers - INFO - User 381283937: sound func;
2020-05-17 23:07:34,132 - conversation.handlers - INFO - User 381283937: animal func;
2020-05-17 23:07:37,943 - conversation.handlers - INFO - User 381283937: stickers func;
2020-05-17 23:07:45,683 - conversation.handlers - INFO - User 381283937: stickers_yes func;
2020-05-17 23:07:45,824 - conversation.handlers - INFO - User 381283937: consent func;
2020-05-18 01:11:04,418 - conversation.handlers - INFO - User 211241527: press /start;
2020-05-18 01:11:06,357 - conversation.handlers - INFO - User 211241527: fruit func;
2020-05-18 01:11:14,981 - conversation.handlers - INFO - User 211241527: sound func;
2020-05-18 01:11:18,672 - conversation.handlers - INFO - User 211241527: animal func;
2020-05-18 01:11:21,154 - conversation.handlers - INFO - User 211241527: stickers func;
2020-05-18 01:11:21,287 - conversation.handlers - INFO - User 211241527: consent func;
2020-05-18 01:33:04,525 - telegram.ext.dispatcher - ERROR - No error handlers are registered, logging exception.
Traceback (most recent call last):
  File "/home/ec2-user/telegram/LAMPA/venv/lib64/python3.6/site-packages/telegram/ext/dispatcher.py", line 343, in process_update
    handler.handle_update(update, self, check, context)
  File "/home/ec2-user/telegram/LAMPA/venv/lib64/python3.6/site-packages/telegram/ext/conversationhandler.py", line 465, in handle_update
    new_state = handler.handle_update(update, dispatcher, check_result, context)
  File "/home/ec2-user/telegram/LAMPA/venv/lib64/python3.6/site-packages/telegram/ext/conversationhandler.py", line 465, in handle_update
    new_state = handler.handle_update(update, dispatcher, check_result, context)
  File "/home/ec2-user/telegram/LAMPA/venv/lib64/python3.6/site-packages/telegram/ext/handler.py", line 119, in handle_update
    return self.callback(update, context)
  File "/home/ec2-user/telegram/LAMPA/lampa-bot/conversation/chat.py", line 50, in answer
    chat_id = update.message.chat.id or update.message.chat_id
AttributeError: 'NoneType' object has no attribute 'chat'
2020-05-18 01:47:48,786 - conversation.handlers - INFO - User 42303979: current_mood func;
2020-05-18 01:47:48,915 - conversation.handlers - INFO - User 211241527: current_mood func;
2020-05-18 01:47:56,391 - conversation.handlers - INFO - User 211241527: press /start;
2020-05-18 01:48:01,776 - conversation.handlers - INFO - User 42303979: press /start;
2020-05-18 07:23:08,172 - matplotlib.category - INFO - Using categorical units to plot a list of strings that are all parsable as floats or dates. If these strings should be plotted as numbers, cast to the appropriate data type before plotting.
2020-05-18 07:23:08,174 - matplotlib.category - INFO - Using categorical units to plot a list of strings that are all parsable as floats or dates. If these strings should be plotted as numbers, cast to the appropriate data type before plotting.
2020-05-18 07:40:07,783 - conversation.payment - INFO - User 68758887: ask Terms;
2020-05-18 09:45:16,396 - conversation.payment - INFO - User 68758887: ask Terms;
2020-05-18 12:18:35,273 - conversation.handlers - INFO - User 142267078: press /start;
2020-05-18 15:19:39,494 - conversation.handlers - INFO - User 152117199: press /start;
2020-05-18 15:19:45,025 - conversation.handlers - INFO - User 152117199: fruit func;
2020-05-18 15:19:52,693 - conversation.handlers - INFO - User 152117199: sound func;
2020-05-18 15:19:58,404 - conversation.handlers - INFO - User 152117199: animal func;
2020-05-18 15:20:07,009 - conversation.handlers - INFO - User 152117199: stickers func;
2020-05-18 15:20:10,905 - conversation.handlers - INFO - User 152117199: stickers_yes func;
2020-05-18 15:20:11,038 - conversation.handlers - INFO - User 152117199: consent func;
